Workbook

Sheet List Deskripsi RO SAP
B3: RO Code | C3: RO DESCRIPTION | D3: SEGMENT CODE | E3: SEGMENT
B4: 140 | C4: MICRO SALES MANAGEMENT DIVISION | D4: M | E4: MICRO
B5: 130 | C5: ULTRA MICRO BUSINESS DIVISION | D5: M | E5: MICRO
B6: 350 | C6: SMALL BUSINESS GROUP (SMALL) | D6: S | E6: SMALL
B7: 360 | C7: COMMERCIAL BUSINESS GROUP | D7: R | E7: COMMERCIAL
B8: 380 | C8: SMALL BUSINESS GROUP (MEDIUM) | D8: D | E8: MEDIUM
B9: 430 | C9: SMALL & MEDIUM SALES MANAGEMENT 2 DIVISION | D9: D | E9: MEDIUM
B10: 280 | C10: TRANSACTION BANKING DIVISION | D10: W | E10: WHOLESALE
B11: 470 | C11: SYNDICATION & FINANCIAL INSTITUTION NON BANK GROUP | D11: K | E11: CORPORATE
B12: 740 | C12: MANUFACTURING, INFRASTRUCTURE, TRANSPORTATION, OIL & GAS GROUP | D12: K | E12: CORPORATE
B13: 750 | C13: INSTITUTIONAL BUSINESS GROUP | D13: K | E13: CORPORATE
B14: 780 | C14: ENERGY & MINING GROUP | D14: K | E14: CORPORATE
B15: 260 | C15: CONSUMER SALES MANAGEMENT 1 | D15: C | E15: CONSUMER
... B24: 390 | C24: FUNDING & RETAIL PAYMENT SALES MANAGEMENT 2 | D24: N | E24: NETWORK & SERVICES

Sheet List FKSEGMEN 20250630
A1: FKSEGMEN | B1: Cek BRD | C1: KET | D1: BIS_OWNER | E1: KET_PRODUK7 | F1: DESKRIPSI | G1: PRODUK_BARU | H1: PRODUK_NEW
A2: 10000 | B2: =VLOOKUP(A2,[1]BRD!A:A,1,0) -> #N/A | C2: Mikro | D2: 5. MIKRO | E2: Kupedes | F2: KREDIT MIKRO | G2: Kupedes | H2: Kupedes
A3: 11000 | B3: =VLOOKUP(A3,[1]BRD!A:A,1,0) -> #N/A | C3: Mikro | D3: 5. MIKRO | E3: Kupedes | F3: KREDIT MIKRO - KOMERSIAL | G3: Kupedes | H3: Kupedes
A4: 11100 | B4: =VLOOKUP(A4,[1]BRD!A:A,1,0) -> #N/A | C4: Mikro | D4: 5. MIKRO | E4: Kupedes | F4: Kupedes | G4: Kupedes | H4: Kupedes
A5: 11200 | B5: =VLOOKUP(A5,[1]BRD!A:A,1,0) -> #N/A | C5: Mikro | D5: 5. MIKRO | E5: KUR Kupedes | F5: KUR Mikro | G5: KUR Kupedes | H5: KUR Kupedes
A6: 11300 | B6: =VLOOKUP(A6,[1]BRD!A:A,1,0) -> #N/A | C6: Mikro | D6: 5. MIKRO | E6: Kupedes Rakyat | F6: Kupedes Rakyat | G6: Kupedes Rakyat | H6: Kupedes Rakyat
A7: 11400 | B7: =VLOOKUP(A7,[1]BRD!A:A,1,0) -> #N/A | C7: Mikro | D7: 5. MIKRO | E7: KUR Kupedes Baru | F7: KUR Mikro Baru | G7: KUR Kupedes Baru | H7: KUR Mikro Baru
A8: 11900 | B8: =VLOOKUP(A8,[1]BRD!A:A,1,0) -> #N/A | C8: Mikro | D8: 5. MIKRO | E8: KUR Ritel Di BRI Unit | F8: KUR Ritel Di BRI Unit | G8: KUR Ritel Di BRI Unit | H8: KUR Ritel Di BRI Unit
A9: 12000 | B9: =VLOOKUP(A9,[1]BRD!A:A,1,0) -> #N/A | C9: Mikro | D9: 5. MIKRO | E9: Kupedes GBT | F9: KREDIT MIKRO - GBT | G9: Kupedes GBT-Kretap | H9: Kupedes Briguna
A10: 20000 | B10: =VLOOKUP(A10,[1]BRD!A:A,1,0) -> 20000 | C10: Commercial | D10: 8. RITEL | E10: Menengah Kanwil | F10: KREDIT MENENGAH | G10: Menengah Kanwil | H10: Menengah
A11: 21000 | B11: =VLOOKUP(A11,[1]BRD!A:A,1,0) -> #N/A | C11: Menengah | D11: 2. BISNIS UMUM | E11: Bisnis Umum | F11: KREDIT MENENGAH - KP | G11: Menengah Kanpus | H11: Menengah
A12: 21010 | B12: =VLOOKUP(A12,[1]BRD!A:A,1,0) -> #N/A | C12: Menengah | D12: 4. AGRIBISNIS | E12: Agribisnis | F12: (AGB) | G12: Menengah Kanpus | H12: Menengah
A13: 21011 | B13: =VLOOKUP(A13,[1]BRD!A:A,1,0) -> #N/A | C13: Menengah | D13: 4. AGRIBISNIS | E13: Agribisnis | F13: (AGB) 1. S/D Rp 5 M | G13: Menengah Kanpus | H13: Menengah
... A170: 82240 | B170: =VLOOKUP(A170,[1]BRD!A:A,1,0) -> 82240 | C170: Small | D170: 12. KECIL | E170: Program (Non KUR) | F170: 01. KREDIT DATA SUP (CF, CG) | G170: KREDIT DATA SUP (CF, CG) | H170: Program Non KUR

Sheet LNPAR
A1: PTYPE | B1: PSHDSC | C1: PTYDSC | D1: PLNGRP | E1: PGRDSC | F1: PGBOOK | G1: PIBASE | H1: PDEPTC | I1: PCURTY | J1: PBKDYS | K1: PMINRT | L1: PMAXRT | M1: PRFLOR | N1: PRCEIL | O1: PINCLU | P1: PFREQ | Q1: PFCODE | R1: PPMTCD | S1: PLATCD | T1: PPDNOT | U1: PCDNOT | V1: PCPN | W1: PMINCG | X1: PCLASS | Y1: PPRCPM | Z1: P1MMPD | AA1: P2MMPD | AB1: P3MMPD | AC1: P4MMPD | AD1: P5MMPD | AE1: P6MMPD | AF1: P1DDPD | AG1: P2DDPD | AH1: P3DDPD | AI1: P4DDPD | AJ1: P5DDPD | AK1: P6DDPD | AL1: PPDRPT | AM1: PMAXLC | AN1: PMNNEW | AO1: PRHSNW | AP1: PRHSPD | AQ1: PRHSPO | AR1: PDHSDY | AS1: PBLNDY | AT1: POTOL | AU1: PMTBOA | AV1: PTAKLC | AW1: PRDTBK | AX1: PRDTDL | AY1: PRDTCL | AZ1: PRDTAH | BA1: PRDTMS | BB1: PRDTTT | BC1: PRLDBK | BD1: PRLDDL | BE1: PRLDCL | BF1: PRLDAH | BG1: PRLDMS | BH1: PRLDTT | BI1: PRMEBK | BJ1: PRMEDL | BK1: PRMECL | BL1: PRMEAH | BM1: PRMEMS | BN1: PRMETT | BO1: PRMTBK | BP1: PRMTDL | BQ1: PRMTCL | BR1: PRMTAH | BS1: PRMTMS | BT1: PRMTTT | BU1: PMNRBK | BV1: PMNRDL | BW1: PMNRCL | BX1: PMNRAH | BY1: PMNRMS | BZ1: PMNRTT | CA1: PRCABK | CB1: PREXBK | CC1: PREXDL | CD1: PREXCL | CE1: PREXAH | CF1: PREXMS | CG1: PREXTT | CH1: PPRCNO | CI1: PBLLBR | CJ1: PRBEXF | CK1: PPRRTC | CL1: PDCBTR | CM1: PMIAMR | CN1: PLCTYP | CO1: PALTSC | CP1: PALTRT | CQ1: PHMAIL | CR1: PRMIND | CS1: PTITLE | CT1: PCLSZR | CU1: PSTATU | CV1: PREAMO | CW1: PESCRO | CX1: PPARTI | CY1: PHASAR | CZ1: PALMTY | DA1: PALWBD | DB1: PBILAW | DC1: PBILDY | DD1: PESCPO | DE1: PDOCTR | DF1: PPPPCD | DG1: PUSESP | DH1: PLSIC1 | DI1: PLSIC2 | DJ1: PLSIC3 | DK1: PLSIC4 | DL1: P1098C | DM1: PCRREP | DN1: PCRTYP | DO1: PCALRE | DP1: PRTCDY | DQ1: PRTCMX | DR1: PRMSUP | DS1: PCLWBK | DT1: PCMRT# | DU1: PCMRT | DV1: PCAPIN | DW1: PCAPLC | DX1: PCAPCA | DY1: PCTYPE | DZ1: PCAPFL | EA1: PACCAP | EB1: PANACT | EC1: PMDINT | ED1: PYRBSE | EE1: PNEAR$ | EF1: PNEARN | EG1: PADJBK | EH1: PCRATE | EI1: PDREST | EJ1: PMRATE | EK1: PDRWDN | EL1: PLONGP | EM1: PLCMC | EN1: PNCRTC | EO1: PKINTR | EP1: PCFPDT | EQ1: PEPEN | ER1: PSHARE | ES1: PPTERM | ET1: PPTMCD | EU1: PPTMIN | EV1: PUPPCD | EW1: PDFPCD | EX1: PBKFUL | EY1: PLSADV | EZ1: PNEGBL | FA1: PUMATD | FB1: PASMAT | FC1: PLSARR | FD1: PCALBK | FE1: PACMC | FF1: PACOC | FG1: PACLC | FH1: PACINT | FI1: PPBMC | FJ1: PPBOC | FK1: PPBLC | FL1: PPBINT | FM1: PMTHBK | FN1: PSIBAS | FO1: PINPAY | FP1: PINALC | FQ1: PINMAT | FR1: PUPDOB | FS1: PDAFP | FT1: PCPAMR | FU1: PROLM | FV1: PDFES# | FW1: PDFESC | FX1: PDFESI | FY1: PUMDRC | FZ1: PUMDCP | GA1: PIFREQ | GB1: PIFCOD | GC1: PCAPMT | GD1: PCAPNP | GE1: PNPLMT | GF1: P#DNPL | GG1: PCPCOM | GH1: PLCLC | GI1: PLCIN | GJ1: PWVELC | GK1: PNPLF | GL1: PCNIPD | GM1: PUPIOB | GN1: PDANIP | GO1: PADVPM | GP1: PSPLTO | GQ1: PADJDD | GR1: PYBSEL | GS1: PYBSEC | GT1: PMINUL | GU1: PMULPC | GV1: PNOADV | GW1: PABKD | GX1: PFFPDT | GY1: POREAM | GZ1: POCPAM | HA1: POABKD | HB1: PBRATE | HC1: PRTPRD | HD1: PFILON | HE1: PFPREP | HF1: PFPRCD | HG1: PFWMTH | HH1: PFPR1 | HI1: PFPR2 | HJ1: PFPR3 | HK1: PFPR4 | HL1: PFPRCT | HM1: PFCANC | HN1: PFCACD | HO1: PFCA1 | HP1: PFCA2 | HQ1: PFCACT | HR1: PFUDRW | HS1: PFUDPC | HT1: PFUDER | HU1: PFUDAR | HV1: PSUPTR | HW1: PPLOPT | HX1: PCARMD | HY1: PMFORG | HZ1: PMFMAT | IA1: PMFNPD | IB1: PINTMT | IC1: PRSTAM | ID1: PINCTV | IE1: PBIAFG
A2: HA | B2: KUPEKS BLN | C2: KUPEDES MK BULANAN | D2: 212 | E2: POnB,Non Prog,KUPEDE | G2: 8 | H2: 110 | I2: IDR | J2: 7 | K2: 0.12 | L2: 0.36 | M2: 0.12 | N2: 0.36 | O2: N | P2: 1 | Q2: M | R2: 0 | S2: 0 | T2: Y | U2: Y | V2: N | W2: 0 | X2: I | Y2: 1 | Z2: 0 | AA2: 0 | AB2: 0 | AC2: 0 | AD2: 0 | AE2: 0 | AF2: 7 | AG2: 21 | AH2: 35 | AI2: 49 | AJ2: 63 | AK2: 77 | AL2: 0 | AM2: 0 | AN2: 0 | AO2: Y | AP2: R | AQ2: 0 | AR2: 0 | AS2: 1 | AT2: 0 | AU2: Y | BC2: 0 | BD2: 0 | BE2: 0 | BF2: 0 | BG2: 0 | BH2: 0 | BI2: N | BJ2: N | BK2: N | BL2: N | BM2: N | BN2: N | BU2: 0 | BV2: 0 | BW2: 0 | BX2: 0 | BY2: 0 | BZ2: 0 | CA2: P | CB2: N | CC2: N | CD2: N | CE2: N | CF2: N | CG2: N | CH2: N | CI2: 0 | CJ2: N | CL2: 0 | CM2: N | CN2: 0 | CO2: N | CP2: N | CQ2: A | CR2: N | CT2: Y | CU2: 4 | CV2: N | CW2: N | CY2: N | DA2: Y | DC2: 0 | DD2: K | DG2: N | DH2: N | DI2: N | DJ2: N | DK2: N | DP2: 0 | DQ2: 0 | DR2: 90 | DS2: 90 | DT2: 0 | DU2: 0 | DV2: N | DW2: P | DX2: P | DY2: 17 | DZ2: N | EC2: F | ED2: 5 | EE2: R | EF2: 100 | EG2: N | EH2: N | EI2: N | EJ2: Z | EK2: N | EL2: 8 | EM2: N | EO2: 0 | EP2: P | EQ2: Y | ER2: N | ES2: 0 | EV2: Y | EW2: 0 | EX2: N | EY2: N | EZ2: N | FA2: N | FB2: Y | FC2: N | FD2: B | FE2: N | FF2: N | FG2: N | FH2: N | FI2: N | FJ2: N | FK2: N | FL2: N | FM2: 0 | FN2: N | FO2: N | FP2: N | FQ2: N | FR2: 0 | FS2: 0 | FT2: N | FV2: 0 | FY2: N | FZ2: N | GA2: 1 | GB2: M | GC2: N | GD2: N | GE2: N | GF2: 0 | GG2: O | GH2: N | GI2: N | GJ2: N | GK2: Y | GL2: N | GM2: 0 | GN2: 0 | GO2: Y | GP2: Y | GQ2: N | GR2: 2 | GS2: 2 | GT2: 0 | GU2: 0 | GV2: 0 | GW2: N | GX2: Y | HB2: N | HC2: 0 | HD2: N | HE2: N | HG2: 0 | HH2: 0 | HI2: 0 | HJ2: 0 | HK2: 0 | HM2: N | HO2: 0 | HP2: 0 | HR2: 0 | HS2: 0 | HT2: 0 | HU2: 0 | HV2: D | HW2: W | HY2: 3 | HZ2: 3 | IA2: 6 | IB2: N | IC2: N | ID2: Y | IE2: N
A3: HB | B3: KUPEKS 3BL | C3: KUPEDES MK 3 BULANAN | D3: 212 | E3: POnB,Non Prog,KUPEDE | G3: 8 | H3: 110 | I3: IDR | J3: 7 | K3: 0.09 | L3: 0.42 | M3: 0.09 | N3: 0.42 | O3: N | P3: 3 | Q3: M | R3: 0 | S3: 0 | T3: Y | U3: Y | V3: N | W3: 0 | X3: I | Y3: 1 | Z3: 0 | AA3: 0 | AB3: 0 | AC3: 0 | AD3: 0 | AE3: 0 | AF3: 7 | AG3: 21 | AH3: 35 | AI3: 49 | AJ3: 63 | AK3: 77 | AL3: 0 | AM3: 0 | AN3: 0 | AO3: Y | AP3: R | AQ3: 0 | AR3: 0 | AS3: 1 | AT3: 0 | AU3: Y | BC3: 0 | BD3: 0 | BE3: 0 | BF3: 0 | BG3: 0 | BH3: 0 | BI3: N | BJ3: N | BK3: N | BL3: N | BM3: N | BN3: N | BU3: 0 | BV3: 0 | BW3: 0 | BX3: 0 | BY3: 0 | BZ3: 0 | CA3: P | CB3: N | CC3: N | CD3: N | CE3: N | CF3: N | CG3: N | CH3: N | CI3: 0 | CJ3: N | CL3: 0 | CM3: N | CN3: 0 | CO3: N | CP3: N | CQ3: A | CR3: N | CT3: Y | CU3: 4 | CV3: N | CW3: N | CY3: N | DA3: Y | DC3: 0 | DD3: K | DG3: N | DH3: N | DI3: N | DJ3: N | DK3: N | DP3: 0 | DQ3: 0 | DR3: 90 | DS3: 90 | DT3: 0 | DU3: 0 | DV3: N | DW3: P | DX3: P | DY3: 17 | DZ3: N | EC3: F | ED3: 5 | EE3: R | EF3: 100 | EG3: N | EH3: N | EI3: N | EJ3: Z | EK3: N | EL3: 8 | EM3: N | EO3: 0 | EP3: P | EQ3: N | ER3: N | ES3: 0 | EV3: Y | EW3: 0 | EX3: N | EY3: N | EZ3: N | FA3: N | FB3: Y | FC3: N | FD3: B | FE3: N | FF3: N | FG3: N | FH3: N | FI3: N | FJ3: N | FK3: N | FL3: N | FM3: 0 | FN3: N | FO3: N | FP3: N | FQ3: N | FR3: 0 | FS3: 0 | FT3: N | FV3: 0 | FY3: N | FZ3: N | GA3: 3 | GB3: M | GC3: N | GD3: N | GE3: N | GF3: 0 | GG3: O | GH3: N | GI3: N | GJ3: N | GK3: Y | GL3: N | GM3: 0 | GN3: 0 | GO3: Y | GP3: Y | GQ3: N | GR3: 2 | GS3: 2 | GT3: 0 | GU3: 0 | GV3: 0 | GW3: N | GX3: Y | HB3: N | HC3: 0 | HD3: N | HE3: N | HG3: 0 | HH3: 0 | HI3: 0 | HJ3: 0 | HK3: 0 | HM3: N | HO3: 0 | HP3: 0 | HR3: 0 | HS3: 0 | HT3: 0 | HU3: 0 | HV3: D | HW3: W | HY3: 3 | HZ3: 3 | IA3: 6 | IB3: N | IC3: N | ID3: Y | IE3: N
A4: HC | B4: KUPEKS 4BL | C4: KUPEDES MK 4 BULANAN | D4: 212 | E4: POnB,Non Prog,KUPEDE | G4: 8 | H4: 110 | I4: IDR | J4: 7 | K4: 0.09 | L4: 0.42 | M4: 0.09 | N4: 0.42 | O4: N | P4: 4 | Q4: M | R4: 0 | S4: 0 | T4: Y | U4: Y | V4: N | W4: 0 | X4: I | Y4: 1 | Z4: 0 | AA4: 0 | AB4: 0 | AC4: 0 | AD4: 0 | AE4: 0 | AF4: 7 | AG4: 21 | AH4: 35 | AI4: 49 | AJ4: 63 | AK4: 77 | AL4: 0 | AM4: 0 | AN4: 0 | AO4: Y | AP4: R | AQ4: 0 | AR4: 0 | AS4: 1 | AT4: 0 | AU4: Y | BC4: 0 | BD4: 0 | BE4: 0 | BF4: 0 | BG4: 0 | BH4: 0 | BI4: N | BJ4: N | BK4: N | BL4: N | BM4: N | BN4: N | BU4: 0 | BV4: 0 | BW4: 0 | BX4: 0 | BY4: 0 | BZ4: 0 | CA4: P | CB4: N | CC4: N | CD4: N | CE4: N | CF4: N | CG4: N | CH4: N | CI4: 0 | CJ4: N | CL4: 0 | CM4: N | CN4: 0 | CO4: N | CP4: N | CQ4: A | CR4: N | CT4: Y | CU4: 4 | CV4: N | CW4: N | CY4: N | DA4: Y | DC4: 0 | DD4: K | DG4: N | DH4: N | DI4: N | DJ4: N | DK4: N | DP4: 0 | DQ4: 0 | DR4: 90 | DS4: 90 | DT4: 0 | DU4: 0 | DV4: N | DW4: P | DX4: P | DY4: 17 | DZ4: N | EC4: F | ED4: 5 | EE4: R | EF4: 100 | EG4: N | EH4: N | EI4: N | EJ4: Z | EK4: N | EL4: 8 | EM4: N | EO4: 0 | EP4: P | EQ4: N | ER4: N | ES4: 0 | EV4: Y | EW4: 0 | EX4: N | EY4: N | EZ4: N | FA4: N | FB4: Y | FC4: N | FD4: B | FE4: N | FF4: N | FG4: N | FH4: N | FI4: N | FJ4: N | FK4: N | FL4: N | FM4: 0 | FN4: N | FO4: N | FP4: N | FQ4: N | FR4: 0 | FS4: 0 | FT4: N | FV4: 0 | FY4: N | FZ4: N | GA4: 4 | GB4: M | GC4: N | GD4: N | GE4: N | GF4: 0 | GG4: O | GH4: N | GI4: N | GJ4: N | GK4: Y | GL4: N | GM4: 0 | GN4: 0 | GO4: Y | GP4: Y | GQ4: N | GR4: 2 | GS4: 2 | GT4: 0 | GU4: 0 | GV4: 0 | GW4: N | GX4: Y | HB4: N | HC4: 0 | HD4: N | HE4: N | HG4: 0 | HH4: 0 | HI4: 0 | HJ4: 0 | HK4: 0 | HM4: N | HO4: 0 | HP4: 0 | HR4: 0 | HS4: 0 | HT4: 0 | HU4: 0 | HV4: D | HW4: W | HY4: 3 | HZ4: 3 | IA4: 6 | IB4: N | IC4: N | ID4: Y | IE4: N
A5: HD | B5: KUPEKS 6BL | C5: KUPEDES MK 6 BULANAN | D5: 212 | E5: POnB,Non Prog,KUPEDE | G5: 8 | H5: 110 | I5: IDR | J5: 7 | K5: 0.09 | L5: 0.42 | M5: 0.09 | N5: 0.42 | O5: N | P5: 6 | Q5: M | R5: 0 | S5: 0 | T5: Y | U5: Y | V5: N | W5: 0 | X5: I | Y5: 1 | Z5: 0 | AA5: 0 | AB5: 0 | AC5: 0 | AD5: 0 | AE5: 0 | AF5: 7 | AG5: 21 | AH5: 35 | AI5: 49 | AJ5: 63 | AK5: 77 | AL5: 0 | AM5: 0 | AN5: 0 | AO5: Y | AP5: R | AQ5: 0 | AR5: 0 | AS5: 1 | AT5: 0 | AU5: Y | BC5: 0 | BD5: 0 | BE5: 0 | BF5: 0 | BG5: 0 | BH5: 0 | BI5: N | BJ5: N | BK5: N | BL5: N | BM5: N | BN5: N | BU5: 0 | BV5: 0 | BW5: 0 | BX5: 0 | BY5: 0 | BZ5: 0 | CA5: P | CB5: N | CC5: N | CD5: N | CE5: N | CF5: N | CG5: N | CH5: N | CI5: 0 | CJ5: N | CL5: 0 | CM5: N | CN5: 0 | CO5: N | CP5: N | CQ5: A | CR5: N | CT5: Y | CU5: 4 | CV5: N | CW5: N | CY5: N | DA5: Y | DC5: 0 | DD5: K | DG5: N | DH5: N | DI5: N | DJ5: N | DK5: N | DP5: 0 | DQ5: 0 | DR5: 90 | DS5: 90 | DT5: 0 | DU5: 0 | DV5: N | DW5: P | DX5: P | DY5: 17 | DZ5: N | EC5: F | ED5: 5 | EE5: R | EF5: 100 | EG5: N | EH5: N | EI5: N | EJ5: Z | EK5: N | EL5: 8 | EM5: N | EO5: 0 | EP5: P | EQ5: N | ER5: N | ES5: 0 | EV5: Y | EW5: 0 | EX5: N | EY5: N | EZ5: N | FA5: N | FB5: Y | FC5: N | FD5: B | FE5: N | FF5: N | FG5: N | FH5: N | FI5: N | FJ5: N | FK5: N | FL5: N | FM5: 0 | FN5: N | FO5: N | FP5: N | FQ5: N | FR5: 0 | FS5: 0 | FT5: N | FV5: 0 | FY5: N | FZ5: N | GA5: 6 | GB5: M | GC5: N | GD5: N | GE5: N | GF5: 0 | GG5: O | GH5: N | GI5: N | GJ5: N | GK5: Y | GL5: N | GM5: 0 | GN5: 0 | GO5: Y | GP5: Y | GQ5: N | GR5: 2 | GS5: 2 | GT5: 0 | GU5: 0 | GV5: 0 | GW5: N | GX5: Y | HB5: N | HC5: 0 | HD5: N | HE5: N | HG5: 0 | HH5: 0 | HI5: 0 | HJ5: 0 | HK5: 0 | HM5: N | HO5: 0 | HP5: 0 | HR5: 0 | HS5: 0 | HT5: 0 | HU5: 0 | HV5: D | HW5: W | HY5: 3 | HZ5: 3 | IA5: 6 | IB5: N | IC5: N | ID5: Y | IE5: N
A6: HE | B6: KUPEKS 1XL | C6: KUPEDES MK 1X LUNAS | D6: 212 | E6: POnB,Non Prog,KUPEDE | G6: 8 | H6: 110 | I6: IDR | J6: 7 | K6: 0.09 | L6: 0.42 | M6: 0.09 | N6: 0.42 | O6: N | P6: 36 | Q6: M | R6: 5 | S6: 0 | T6: Y | U6: Y | V6: N | W6: 0 | X6: I | Y6: 1 | Z6: 0 | AA6: 0 | AB6: 0 | AC6: 0 | AD6: 0 | AE6: 0 | AF6: 7 | AG6: 21 | AH6: 35 | AI6: 49 | AJ6: 63 | AK6: 77 | AL6: 0 | AM6: 0 | AN6: 0 | AO6: Y | AP6: R | AQ6: 0 | AR6: 0 | AS6: 1 | AT6: 0 | AU6: Y | BC6: 0 | BD6: 0 | BE6: 0 | BF6: 0 | BG6: 0 | BH6: 0 | BI6: N | BJ6: N | BK6: N | BL6: N | BM6: N | BN6: N | BU6: 0 | BV6: 0 | BW6: 0 | BX6: 0 | BY6: 0 | BZ6: 0 | CA6: P | CB6: N | CC6: N | CD6: N | CE6: N | CF6: N | CG6: N | CH6: N | CI6: 0 | CJ6: N | CL6: 0 | CM6: N | CN6: 0 | CO6: N | CP6: N | CQ6: A | CR6: N | CT6: Y | CU6: 4 | CV6: N | CW6: N | CY6: N | DA6: Y | DC6: 0 | DD6: K | DG6: N | DH6: N | DI6: N | DJ6: N | DK6: N | DP6: 0 | DQ6: 0 | DR6: 90 | DS6: 90 | DT6: 0 | DU6: 0 | DV6: N | DW6: P | DX6: P | DY6: 17 | DZ6: N | EC6: F | ED6: 5 | EE6: R | EF6: 100 | EG6: N | EH6: N | EI6: N | EJ6: Z | EK6: N | EL6: 8 | EM6: N | EO6: 0 | EP6: X | EQ6: N | ER6: N | ES6: 0 | EV6: Y | EW6: 5 | EX6: N | EY6: N | EZ6: N | FA6: N | FB6: Y | FC6: N | FD6: B | FE6: N | FF6: N | FG6: N | FH6: N | FI6: N | FJ6: N | FK6: N | FL6: N | FM6: 0 | FN6: N | FO6: N | FP6: N | FQ6: N | FR6: 0 | FS6: 0 | FT6: N | FV6: 0 | FY6: N | FZ6: N | GA6: 36 | GB6: M | GC6: N | GD6: N | GE6: N | GF6: 0 | GG6: O | GH6: N | GI6: N | GJ6: N | GK6: Y | GL6: N | GM6: 0 | GN6: 0 | GO6: Y | GP6: Y | GQ6: N | GR6: 2 | GS6: 2 | GT6: 0 | GU6: 0 | GV6: 0 | GW6: N | GX6: Y | HB6: N | HC6: 0 | HD6: N | HE6: N | HG6: 0 | HH6: 0 | HI6: 0 | HJ6: 0 | HK6: 0 | HM6: N | HO6: 0 | HP6: 0 | HR6: 0 | HS6: 0 | HT6: 0 | HU6: 0 | HV6: D | HW6: W | HY6: 3 | HZ6: 3 | IA6: 6 | IB6: N | IC6: N | ID6: Y | IE6: N
A7: HM | B7: KUPIN 1XL | C7: KUPEDES INV 1X LUNAS | D7: 212 | E7: POnB,Non Prog,KUPEDE | G7: 8 | H7: 110 | I7: IDR | J7: 7 | K7: 0.09 | L7: 0.42 | M7: 0.09 | N7: 0.42 | O7: N | P7: 36 | Q7: M | R7: 5 | S7: 0 | T7: Y | U7: Y | V7: N | W7: 0 | X7: I | Y7: 1 | Z7: 0 | AA7: 0 | AB7: 0 | AC7: 0 | AD7: 0 | AE7: 0 | AF7: 7 | AG7: 21 | AH7: 35 | AI7: 49 | AJ7: 63 | AK7: 77 | AL7: 0 | AM7: 0 | AN7: 0 | AO7: Y | AP7: R | AQ7: 0 | AR7: 0 | AS7: 1 | AT7: 0 | AU7: Y | BC7: 0 | BD7: 0 | BE7: 0 | BF7: 0 | BG7: 0 | BH7: 0 | BI7: N | BJ7: N | BK7: N | BL7: N | BM7: N | BN7: N | BU7: 0 | BV7: 0 | BW7: 0 | BX7: 0 | BY7: 0 | BZ7: 0 | CA7: P | CB7: N | CC7: N | CD7: N | CE7: N | CF7: N | CG7: N | CH7: N | CI7: 0 | CJ7: N | CL7: 0 | CM7: N | CN7: 0 | CO7: N | CP7: N | CQ7: A | CR7: N | CT7: Y | CU7: 4 | CV7: N | CW7: N | CY7: N | DA7: Y | DC7: 0 | DD7: K | DG7: N | DH7: N | DI7: N | DJ7: N | DK7: N | DP7: 0 | DQ7: 0 | DR7: 90 | DS7: 90 | DT7: 0 | DU7: 0 | DV7: N | DW7: P | DX7: P | DY7: 17 | DZ7: N | EC7: F | ED7: 5 | EE7: R | EF7: 100 | EG7: N | EH7: N | EI7: N | EJ7: Z | EK7: N | EL7: 8 | EM7: N | EO7: 0 | EP7: X | EQ7: N | ER7: N | ES7: 0 | EV7: Y | EW7: 5 | EX7: N | EY7: N | EZ7: N | FA7: N | FB7: Y | FC7: N | FD7: B | FE7: N | FF7: N | FG7: N | FH7: N | FI7: N | FJ7: N | FK7: N | FL7: N | FM7: 0 | FN7: N | FO7: N | FP7: N | FQ7: N | FR7: 0 | FS7: 0 | FT7: N | FV7: 0 | FY7: N | FZ7: N | GA7: 36 | GB7: M | GC7: N | GD7: N | GE7: N | GF7: 0 | GG7: O | GH7: N | GI7: N | GJ7: N | GK7: Y | GL7: N | GM7: 0 | GN7: 0 | GO7: Y | GP7: Y | GQ7: N | GR7: 2 | GS7: 2 | GT7: 0 | GU7: 0 | GV7: 0 | GW7: N | GX7: Y | HB7: N | HC7: 0 | HD7: N | HE7: N | HG7: 0 | HH7: 0 | HI7: 0 | HJ7: 0 | HK7: 0 | HM7: N | HO7: 0 | HP7: 0 | HR7: 0 | HS7: 0 | HT7: 0 | HU7: 0 | HV7: D | HW7: W | HY7: 3 | HZ7: 3 | IA7: 6 | IB7: N | IC7: N | ID7: Y | IE7: N
A8: HI | B8: KUPIN BLN | C8: KUPEDES INV BULANAN | D8: 212 | E8: KUPEDES, Divisi Mikr | G8: 8 | H8: 110 | I8: IDR | J8: 7 | K8: 0.12 | L8: 0.36 | M8: 0.12 | N8: 0.36 | O8: N | P8: 1 | Q8: M | R8: 0 | S8: 0 | T8: Y | U8: Y | V8: N | W8: 0 | X8: I | Y8: 1 | Z8: 0 | AA8: 0 | AB8: 0 | AC8: 0 | AD8: 0 | AE8: 0 | AF8: 7 | AG8: 21 | AH8: 35 | AI8: 49 | AJ8: 63 | AK8: 77 | AL8: 0 | AM8: 0 | AN8: 0 | AO8: Y | AP8: R | AQ8: 0 | AR8: 0 | AS8: 1 | AT8: 0 | AU8: Y | BC8: 0 | BD8: 0 | BE8: 0 | BF8: 0 | BG8: 0 | BH8: 0 | BI8: N | BJ8: N | BK8: N | BL8: N | BM8: N | BN8: N | BU8: 0 | BV8: 0 | BW8: 0 | BX8: 0 | BY8: 0 | BZ8: 0 | CA8: P | CB8: N | CC8: N | CD8: N | CE8: N | CF8: N | CG8: N | CH8: N | CI8: 0 | CJ8: N | CL8: 0 | CM8: N | CN8: 0 | CO8: N | CP8: N | CQ8: A | CR8: N | CT8: Y | CU8: 4 | CV8: N | CW8: N | CY8: N | DA8: Y | DC8: 0 | DD8: K | DG8: N | DH8: N | DI8: N | DJ8: N | DK8: N | DP8: 0 | DQ8: 0 | DR8: 90 | DS8: 90 | DT8: 0 | DU8: 0 | DV8: N | DW8: P | DX8: P | DY8: 17 | DZ8: N | EC8: F | ED8: 5 | EE8: R | EF8: 100 | EG8: N | EH8: N | EI8: N | EJ8: Z | EK8: N | EL8: 8 | EM8: N | EO8: 0 | EP8: P | EQ8: Y | ER8: N | ES8: 0 | EV8: Y | EW8: 0 | EX8: N | EY8: N | EZ8: N | FA8: N | FB8: Y | FC8: N | FD8: B | FE8: N | FF8: N | FG8: N | FH8: N | FI8: N | FJ8: N | FK8: N | FL8: N | FM8: 0 | FN8: N | FO8: N | FP8: N | FQ8: N | FR8: 0 | FS8: 0 | FT8: N | FV8: 0 | FY8: N | FZ8: N | GA8: 1 | GB8: M | GC8: N | GD8: N | GE8: N | GF8: 0 | GG8: O | GH8: N | GI8: N | GJ8: N | GK8: Y | GL8: N | GM8: 0 | GN8: 0 | GO8: Y | GP8: Y | GQ8: N | GR8: 2 | GS8: 2 | GT8: 0 | GU8: 0 | GV8: 0 | GW8: N | GX8: Y | HB8: N | HC8: 0 | HD8: N | HE8: N | HG8: 0 | HH8: 0 | HI8: 0 | HJ8: 0 | HK8: 0 | HM8: N | HO8: 0 | HP8: 0 | HR8: 0 | HS8: 0 | HT8: 0 | HU8: 0 | HV8: D | HW8: W | HY8: 3 | HZ8: 3 | IA8: 6 | IB8: N | IC8: N | ID8: Y | IE8: N
A9: HJ | B9: KUPIN 3BLN | C9: KUPEDES INV 3BULANAN | D9: 212 | E9: POnB,Non Prog,KUPEDE | G9: 8 | H9: 110 | I9: IDR | J9: 7 | K9: 0.09 | L9: 0.42 | M9: 0.09 | N9: 0.42 | O9: N | P9: 3 | Q9: M | R9: 0 | S9: 0 | T9: Y | U9: Y | V9: N | W9: 0 | X9: I | Y9: 1 | Z9: 0 | AA9: 0 | AB9: 0 | AC9: 0 | AD9: 0 | AE9: 0 | AF9: 7 | AG9: 21 | AH9: 35 | AI9: 49 | AJ9: 63 | AK9: 77 | AL9: 0 | AM9: 0 | AN9: 0 | AO9: Y | AP9: R | AQ9: 0 | AR9: 0 | AS9: 1 | AT9: 0 | AU9: Y | BC9: 0 | BD9: 0 | BE9: 0 | BF9: 0 | BG9: 0 | BH9: 0 | BI9: N | BJ9: N | BK9: N | BL9: N | BM9: N | BN9: N | BU9: 0 | BV9: 0 | BW9: 0 | BX9: 0 | BY9: 0 | BZ9: 0 | CA9: P | CB9: N | CC9: N | CD9: N | CE9: N | CF9: N | CG9: N | CH9: N | CI9: 0 | CJ9: N | CL9: 0 | CM9: N | CN9: 0 | CO9: N | CP9: N | CQ9: A | CR9: N | CT9: Y | CU9: 4 | CV9: N | CW9: N | CY9: N | DA9: Y | DC9: 0 | DD9: K | DG9: N | DH9: N | DI9: N | DJ9: N | DK9: N | DP9: 0 | DQ9: 0 | DR9: 90 | DS9: 90 | DT9: 0 | DU9: 0 | DV9: N | DW9: P | DX9: P | DY9: 17 | DZ9: N | EC9: F | ED9: 5 | EE9: R | EF9: 100 | EG9: N | EH9: N | EI9: N | EJ9: Z | EK9: N | EL9: 8 | EM9: N | EO9: 0 | EP9: P | EQ9: N | ER9: N | ES9: 0 | EV9: Y | EW9: 0 | EX9: N | EY9: N | EZ9: N | FA9: N | FB9: Y | FC9: N | FD9: B | FE9: N | FF9: N | FG9: N | FH9: N | FI9: N | FJ9: N | FK9: N | FL9: N | FM9: 0 | FN9: N | FO9: N | FP9: N | FQ9: N | FR9: 0 | FS9: 0 | FT9: N | FV9: 0 | FY9: N | FZ9: N | GA9: 3 | GB9: M | GC9: N | GD9: N | GE9: N | GF9: 0 | GG9: O | GH9: N | GI9: N | GJ9: N | GK9: Y | GL9: N | GM9: 0 | GN9: 0 | GO9: Y | GP9: Y | GQ9: N | GR9: 2 | GS9: 2 | GT9: 0 | GU9: 0 | GV9: 0 | GW9: N | GX9: Y | HB9: N | HC9: 0 | HD9: N | HE9: N | HG9: 0 | HH9: 0 | HI9: 0 | HJ9: 0 | HK9: 0 | HM9: N | HO9: 0 | HP9: 0 | HR9: 0 | HS9: 0 | HT9: 0 | HU9: 0 | HV9: D | HW9: W | HY9: 3 | HZ9: 3 | IA9: 6 | IB9: N | IC9: N | ID9: Y | IE9: N
A10: HK | B10: KUPIN 4BLN | C10: KUPEDES INV 4BULANAN | D10: 212 | E10: POnB,Non Prog,KUPEDE | G10: 8 | H10: 110 | I10: IDR | J10: 7 | K10: 0.09 | L10: 0.42 | M10: 0.09 | N10: 0.42 | O10: N | P10: 4 | Q10: M | R10: 0 | S10: 0 | T10: Y | U10: Y | V10: N | W10: 0 | X10: I | Y10: 1 | Z10: 0 | AA10: 0 | AB10: 0 | AC10: 0 | AD10: 0 | AE10: 0 | AF10: 7 | AG10: 21 | AH10: 35 | AI10: 49 | AJ10: 63 | AK10: 77 | AL10: 0 | AM10: 0 | AN10: 0 | AO10: Y | AP10: R | AQ10: 0 | AR10: 0 | AS10: 1 | AT10: 0 | AU10: Y | BC10: 0 | BD10: 0 | BE10: 0 | BF10: 0 | BG10: 0 | BH10: 0 | BI10: N | BJ10: N | BK10: N | BL10: N | BM10: N | BN10: N | BU10: 0 | BV10: 0 | BW10: 0 | BX10: 0 | BY10: 0 | BZ10: 0 | CA10: P | CB10: N | CC10: N | CD10: N | CE10: N | CF10: N | CG10: N | CH10: N | CI10: 0 | CJ10: N | CL10: 0 | CM10: N | CN10: 0 | CO10: N | CP10: N | CQ10: A | CR10: N | CT10: Y | CU10: 4 | CV10: N | CW10: N | CY10: N | DA10: Y | DC10: 0 | DD10: K | DG10: N | DH10: N | DI10: N | DJ10: N | DK10: N | DP10: 0 | DQ10: 0 | DR10: 90 | DS10: 90 | DT10: 0 | DU10: 0 | DV10: N | DW10: P | DX10: P | DY10: 17 | DZ10: N | EC10: F | ED10: 5 | EE10: R | EF10: 100 | EG10: N | EH10: N | EI10: N | EJ10: Z | EK10: N | EL10: 8 | EM10: N | EO10: 0 | EP10: P | EQ10: N | ER10: N | ES10: 0 | EV10: Y | EW10: 0 | EX10: N | EY10: N | EZ10: N | FA10: N | FB10: Y | FC10: N | FD10: B | FE10: N | FF10: N | FG10: N | FH10: N | FI10: N | FJ10: N | FK10: N | FL10: N | FM10: 0 | FN10: N | FO10: N | FP10: N | FQ10: N | FR10: 0 | FS10: 0 | FT10: N | FV10: 0 | FY10: N | FZ10: N | GA10: 4 | GB10: M | GC10: N | GD10: N | GE10: N | GF10: 0 | GG10: O | GH10: N | GI10: N | GJ10: N | GK10: Y | GL10: N | GM10: 0 | GN10: 0 | GO10: Y | GP10: Y | GQ10: N | GR10: 2 | GS10: 2 | GT10: 0 | GU10: 0 | GV10: 0 | GW10: N | GX10: Y | HB10: N | HC10: 0 | HD10: N | HE10: N | HG10: 0 | HH10: 0 | HI10: 0 | HJ10: 0 | HK10: 0 | HM10: N | HO10: 0 | HP10: 0 | HR10: 0 | HS10: 0 | HT10: 0 | HU10: 0 | HV10: D | HW10: W | HY10: 3 | HZ10: 3 | IA10: 6 | IB10: N | IC10: N | ID10: Y | IE10: N
A11: HL | B11: KUPIN 6BLN | C11: KUPEDES INV 6BULANAN | D11: 212 | E11: POnB,Non Prog,KUPEDE | G11: 8 | H11: 110 | I11: IDR | J11: 7 | K11: 0.09 | L11: 0.42 | M11: 0.09 | N11: 0.42 | O11: N | P11: 6 | Q11: M | R11: 0 | S11: 0 | T11: Y | U11: Y | V11: N | W11: 0 | X11: I | Y11: 1 | Z11: 0 | AA11: 0 | AB11: 0 | AC11: 0 | AD11: 0 | AE11: 0 | AF11: 7 | AG11: 21 | AH11: 35 | AI11: 49 | AJ11: 63 | AK11: 77 | AL11: 0 | AM11: 0 | AN11: 0 | AO11: Y | AP11: R | AQ11: 0 | AR11: 0 | AS11: 1 | AT11: 0 | AU11: Y | BC11: 0 | BD11: 0 | BE11: 0 | BF11: 0 | BG11: 0 | BH11: 0 | BI11: N | BJ11: N | BK11: N | BL11: N | BM11: N | BN11: N | BU11: 0 | BV11: 0 | BW11: 0 | BX11: 0 | BY11: 0 | BZ11: 0 | CA11: P | CB11: N | CC11: N | CD11: N | CE11: N | CF11: N | CG11: N | CH11: N | CI11: 0 | CJ11: N | CL11: 0 | CM11: N | CN11: 0 | CO11: N | CP11: N | CQ11: A | CR11: N | CT11: Y | CU11: 4 | CV11: N | CW11: N | CY11: N | DA11: Y | DC11: 0 | DD11: K | DG11: N | DH11: N | DI11: N | DJ11: N | DK11: N | DP11: 0 | DQ11: 0 | DR11: 90 | DS11: 90 | DT11: 0 | DU11: 0 | DV11: N | DW11: P | DX11: P | DY11: 17 | DZ11: N | EC11: F | ED11: 5 | EE11: R | EF11: 100 | EG11: N | EH11: N | EI11: N | EJ11: Z | EK11: N | EL11: 8 | EM11: N | EO11: 0 | EP11: P | EQ11: N | ER11: N | ES11: 0 | EV11: Y | EW11: 0 | EX11: N | EY11: N | EZ11: N | FA11: N | FB11: Y | FC11: N | FD11: B | FE11: N | FF11: N | FG11: N | FH11: N | FI11: N | FJ11: N | FK11: N | FL11: N | FM11: 0 | FN11: N | FO11: N | FP11: N | FQ11: N | FR11: 0 | FS11: 0 | FT11: N | FV11: 0 | FY11: N | FZ11: N | GA11: 6 | GB11: M | GC11: N | GD11: N | GE11: N | GF11: 0 | GG11: O | GH11: N | GI11: N | GJ11: N | GK11: Y | GL11: N | GM11: 0 | GN11: 0 | GO11: Y | GP11: Y | GQ11: N | GR11: 2 | GS11: 2 | GT11: 0 | GU11: 0 | GV11: 0 | GW11: N | GX11: Y | HB11: N | HC11: 0 | HD11: N | HE11: N | HG11: 0 | HH11: 0 | HI11: 0 | HJ11: 0 | HK11: 0 | HM11: N | HO11: 0 | HP11: 0 | HR11: 0 | HS11: 0 | HT11: 0 | HU11: 0 | HV11: D | HW11: W | HY11: 3 | HZ11: 3 | IA11: 6 | IB11: N | IC11: N | ID11: Y | IE11: N
A12: HF | B12: KUPEKS 3GP | C12: KUPEDES MK 3 BLN GP | D12: 212 | E12: POnB,Non Prog,KUPEDE | G12: 8 | H12: 110 | I12: IDR | J12: 7 | K12: 0.12 | L12: 0.42 | M12: 0.12 | N12: 0.42 | O12: N | P12: 1 | Q12: M | R12: 0 | S12: 0 | T12: Y | U12: Y | V12: N | W12: 0 | X12: I | Y12: 1 | Z12: 0 | AA12: 0 | AB12: 0 | AC12: 0 | AD12: 0 | AE12: 0 | AF12: 7 | AG12: 21 | AH12: 35 | AI12: 49 | AJ12: 63 | AK12: 77 | AL12: 0 | AM12: 0 | AN12: 0 | AO12: Y | AP12: R | AQ12: 0 | AR12: 0 | AS12: 1 | AT12: 0 | AU12: Y | BC12: 0 | BD12: 0 | BE12: 0 | BF12: 0 | BG12: 0 | BH12: 0 | BI12: N | BJ12: N | BK12: N | BL12: N | BM12: N | BN12: N | BU12: 0 | BV12: 0 | BW12: 0 | BX12: 0 | BY12: 0 | BZ12: 0 | CA12: P | CB12: N | CC12: N | CD12: N | CE12: N | CF12: N | CG12: N | CH12: N | CI12: 0 | CJ12: N | CL12: 0 | CM12: N | CN12: 0 | CO12: N | CP12: N | CQ12: A | CR12: N | CT12: Y | CU12: 4 | CV12: N | CW12: N | CY12: N | DA12: Y | DC12: 0 | DD12: K | DG12: N | DH12: N | DI12: N | DJ12: N | DK12: N | DP12: 0 | DQ12: 0 | DR12: 90 | DS12: 90 | DT12: 0 | DU12: 0 | DV12: N | DW12: P | DX12: P | DY12: 17 | DZ12: N | EC12: F | ED12: 5 | EE12: R | EF12: 100 | EG12: N | EH12: N | EI12: N | EJ12: Z | EK12: N | EL12: 8 | EM12: N | EO12: 0 | EP12: P | EQ12: N | ER12: N | ES12: 0 | EV12: Y | EW12: 0 | EX12: N | EY12: N | EZ12: N | FA12: N | FB12: Y | FC12: N | FD12: B | FE12: N | FF12: N | FG12: N | FH12: N | FI12: N | FJ12: N | FK12: N | FL12: N | FM12: 3 | FN12: N | FO12: N | FP12: N | FQ12: N | FR12: 0 | FS12: 0 | FT12: N | FV12: 0 | FY12: N | FZ12: N | GA12: 1 | GB12: M | GC12: N | GD12: N | GE12: N | GF12: 0 | GG12: O | GH12: N | GI12: N | GJ12: N | GK12: Y | GL12: N | GM12: 0 | GN12: 0 | GO12: Y | GP12: Y | GQ12: N | GR12: 2 | GS12: 2 | GT12: 0 | GU12: 0 | GV12: 0 | GW12: N | GX12: Y | HB12: N | HC12: 0 | HD12: N | HE12: N | HG12: 0 | HH12: 0 | HI12: 0 | HJ12: 0 | HK12: 0 | HM12: N | HO12: 0 | HP12: 0 | HR12: 0 | HS12: 0 | HT12: 0 | HU12: 0 | HV12: D | HW12: W | HY12: 3 | HZ12: 3 | IA12: 6 | IB12: Y | IC12: Y | ID12: Y | IE12: N
A13: HG | B13: KUPEKS 6GP | C13: KUPEDES MK 6 BLN GP | D13: 212 | E13: POnB,Non Prog,KUPEDE | G13: 8 | H13: 110 | I13: IDR | J13: 7 | K13: 0.12 | L13: 0.42 | M13: 0.12 | N13: 0.42 | O13: N | P13: 1 | Q13: M | R13: 0 | S13: 0 | T13: Y | U13: Y | V13: N | W13: 0 | X13: I | Y13: 1 | Z13: 0 | AA13: 0 | AB13: 0 | AC13: 0 | AD13: 0 | AE13: 0 | AF13: 7 | AG13: 21 | AH13: 35 | AI13: 49 | AJ13: 63 | AK13: 77 | AL13: 0 | AM13: 0 | AN13: 0 | AO13: Y | AP13: R | AQ13: 0 | AR13: 0 | AS13: 1 | AT13: 0 | AU13: Y | BC13: 0 | BD13: 0 | BE13: 0 | BF13: 0 | BG13: 0 | BH13: 0 | BI13: N | BJ13: N | BK13: N | BL13: N | BM13: N | BN13: N | BU13: 0 | BV13: 0 | BW13: 0 | BX13: 0 | BY13: 0 | BZ13: 0 | CA13: P | CB13: N | CC13: N | CD13: N | CE13: N | CF13: N | CG13: N | CH13: N | CI13: 0 | CJ13: N | CL13: 0 | CM13: N | CN13: 0 | CO13: N | CP13: N | CQ13: A | CR13: N | CT13: Y | CU13: 4 | CV13: N | CW13: N | CY13: N | DA13: Y | DC13: 0 | DD13: K | DG13: N | DH13: N | DI13: N | DJ13: N | DK13: N | DP13: 0 | DQ13: 0 | DR13: 90 | DS13: 90 | DT13: 0 | DU13: 0 | DV13: N | DW13: P | DX13: P | DY13: 17 | DZ13: N | EC13: F | ED13: 5 | EE13: R | EF13: 100 | EG13: N | EH13: N | EI13: N | EJ13: Z | EK13: N | EL13: 8 | EM13: N | EO13: 0 | EP13: P | EQ13: N | ER13: N | ES13: 0 | EV13: Y | EW13: 0 | EX13: N | EY13: N | EZ13: N | FA13: N | FB13: Y | FC13: N | FD13: B | FE13: N | FF13: N | FG13: N | FH13: N | FI13: N | FJ13: N | FK13: N | FL13: N | FM13: 6 | FN13: N | FO13: N | FP13: N | FQ13: N | FR13: 0 | FS13: 0 | FT13: N | FV13: 0 | FY13: N | FZ13: N | GA13: 1 | GB13: M | GC13: N | GD13: N | GE13: N | GF13: 0 | GG13: O | GH13: N | GI13: N | GJ13: N | GK13: Y | GL13: N | GM13: 0 | GN13: 0 | GO13: Y | GP13: Y | GQ13: N | GR13: 2 | GS13: 2 | GT13: 0 | GU13: 0 | GV13: 0 | GW13: N | GX13: Y | HB13: N | HC13: 0 | HD13: N | HE13: N | HG13: 0 | HH13: 0 | HI13: 0 | HJ13: 0 | HK13: 0 | HM13: N | HO13: 0 | HP13: 0 | HR13: 0 | HS13: 0 | HT13: 0 | HU13: 0 | HV13: D | HW13: W | HY13: 3 | HZ13: 3 | IA13: 6 | IB13: Y | IC13: Y | ID13: Y | IE13: N
... A18: HQ | B18: KUPTAP | C18: KUPEDES GOLBERTAP | D18: 212 | E18: KUPEDES, Divisi Mikr | G18: 8 | H18: 110 | I18: IDR | J18: 7 | K18: 0.12 | L18: 0.36 | M18: 0.12 | N18: 0.36 | O18: N | P18: 1 | Q18: M | R18: 0 | S18: 0 | T18: Y | U18: Y | V18: N | W18: 0 | X18: I | Y18: 1 | Z18: 0 | AA18: 0 | AB18: 0 | AC18: 0 | AD18: 0 | AE18: 0 | AF18: 7 | AG18: 21 | AH18: 35 | AI18: 49 | AJ18: 63 | AK18: 77 | AL18: 0 | AM18: 0 | AN18: 0 | AO18: Y | AP18: R | AQ18: 0 | AR18: 0 | AS18: 26 | AT18: 0 | AU18: Y | BC18: 0 | BD18: 0 | BE18: 0 | BF18: 0 | BG18: 0 | BH18: 0 | BI18: N | BJ18: N | BK18: N | BL18: N | BM18: N | BN18: N | BU18: 0 | BV18: 0 | BW18: 0 | BX18: 0 | BY18: 0 | BZ18: 0 | CA18: P | CB18: N | CC18: N | CD18: N | CE18: N | CF18: N | CG18: N | CH18: N | CI18: 0 | CJ18: N | CL18: 0 | CM18: N | CN18: 0 | CO18: N | CP18: N | CQ18: A | CR18: N | CT18: Y | CU18: 4 | CV18: N | CW18: N | CY18: N | DA18: Y | DC18: 0 | DD18: K | DG18: N | DH18: N | DI18: N | DJ18: N | DK18: N | DP18: 0 | DQ18: 0 | DR18: 90 | DS18: 90 | DT18: 0 | DU18: 0 | DV18: N | DW18: P | DX18: P | DY18: 17 | DZ18: N | EC18: F | ED18: 5 | EE18: R | EF18: 100 | EG18: N | EH18: N | EI18: N | EJ18: Z | EK18: N | EL18: 8 | EM18: N | EO18: 0 | EP18: P | EQ18: Y | ER18: N | ES18: 0 | EV18: Y | EW18: 0 | EX18: N | EY18: N | EZ18: N | FA18: N | FB18: Y | FC18: N | FD18: B | FE18: N | FF18: N | FG18: N | FH18: N | FI18: N | FJ18: N | FK18: N | FL18: N | FM18: 0 | FN18: N | FO18: N | FP18: N | FQ18: N | FR18: 0 | FS18: 0 | FT18: N | FV18: 0 | FY18: N | FZ18: N | GA18: 1 | GB18: M | GC18: N | GD18: N | GE18: N | GF18: 0 | GG18: O | GH18: N | GI18: N | GJ18: N | GK18: Y | GL18: N | GM18: 0 | GN18: 0 | GO18: Y | GP18: Y | GQ18: N | GR18: 2 | GS18: 2 | GT18: 0 | GU18: 0 | GV18: 0 | GW18: N | GX18: Y | HB18: N | HC18: 0 | HD18: Y | HE18: N | HG18: 0 | HH18: 0 | HI18: 0 | HJ18: 0 | HK18: 0 | HM18: N | HO18: 0 | HP18: 0 | HR18: 0 | HS18: 0 | HT18: 0 | HU18: 0 | HV18: D | HW18: W | HY18: 0 | HZ18: 0 | IA18: 0 | IB18: N | IC18: N | ID18: Y | IE18: N
A19: FH | B19: BRIGuna | C19: BRIGuna (KRETAP) | D19: 210 | E19: POnB,Non Prog,Konsum | G19: 8 | H19: 230 | I19: IDR | J19: 31 | K19: 0.007 | L19: 0.24 | M19: 0.007 | N19: 0.24 | O19: N | P19: 1 | Q19: M | R19: 0 | S19: 11 | T19: Y | U19: Y | V19: N | W19: 0 | X19: I | Y19: 1 | Z19: 0 | AA19: 0 | AB19: 0 | AC19: 0 | AD19: 0 | AE19: 0 | AF19: 7 | AG19: 21 | AH19: 36 | AI19: 49 | AJ19: 63 | AK19: 77 | AL19: 0 | AM19: 0 | AN19: 0 | AO19: Y | AP19: R | AQ19: 0 | AR19: 0 | AS19: 26 | AT19: 0 | AU19: Y | BC19: 0 | BD19: 0 | BE19: 0 | BF19: 0 | BG19: 0 | BH19: 0 | BI19: N | BJ19: N | BK19: N | BL19: N | BM19: N | BN19: N | BU19: 0 | BV19: 0 | BW19: 0 | BX19: 0 | BY19: 0 | BZ19: 0 | CA19: P | CB19: N | CC19: N | CD19: N | CE19: N | CF19: N | CG19: N | CH19: N | CI19: 0 | CJ19: N | CL19: 0 | CM19: N | CN19: 0 | CO19: N | CP19: N | CQ19: B | CR19: N | CT19: N | CU19: 4 | CV19: N | CW19: N | CY19: N | DA19: Y | DC19: 0 | DD19: T | DG19: N | DH19: N | DI19: N | DJ19: N | DK19: N | DP19: 0 | DQ19: 0 | DR19: 90 | DS19: 90 | DT19: 0 | DU19: 0 | DV19: N | DW19: P | DY19: 17 | DZ19: N | EC19: F | ED19: 5 | EE19: U | EF19: 100 | EG19: N | EH19: N | EI19: N | EJ19: N | EK19: N | EL19: 6 | EM19: N | EO19: 99 | EP19: P | EQ19: Y | ER19: N | ES19: 0 | EV19: Y | EW19: 0 | EX19: N | EY19: N | EZ19: N | FA19: N | FB19: Y | FC19: N | FD19: B | FE19: N | FF19: N | FG19: N | FH19: N | FI19: N | FJ19: N | FK19: N | FL19: N | FM19: 0 | FN19: N | FO19: N | FP19: N | FQ19: N | FR19: 0 | FS19: 0 | FT19: N | FV19: 0 | FY19: N | FZ19: N | GA19: 1 | GB19: M | GC19: N | GD19: N | GE19: N | GF19: 0 | GG19: O | GH19: N | GI19: N | GJ19: N | GK19: Y | GL19: N | GM19: 0 | GN19: 0 | GO19: Y | GP19: Y | GQ19: N | GR19: 0 | GS19: 0 | GT19: 0 | GU19: 0 | GV19: 0 | GW19: N | GX19: Y | HB19: N | HC19: 0 | HD19: N | HE19: Y | HF19: O | HG19: 0 | HH19: 0 | HI19: 0 | HJ19: 0 | HK19: 0 | HL19: 18 | HM19: N | HO19: 0 | HP19: 0 | HR19: 0 | HS19: 0 | HT19: 0 | HU19: 0 | HV19: D | HW19: W | HY19: 0 | HZ19: 0 | IA19: 0 | IB19: N | IC19: N | ID19: N | IE19: N
A20: FI | B20: BRIGunaSUN | C20: BRIGunaSUN TASPEN | D20: 210 | E20: POnB,Non Prog,Konsum | G20: 8 | H20: 230 | I20: IDR | J20: 31 | K20: 0.007 | L20: 0.24 | M20: 0.007 | N20: 0.24 | O20: N | P20: 1 | Q20: M | R20: 0 | S20: 11 | T20: Y | U20: Y | V20: N | W20: 0 | X20: I | Y20: 1 | Z20: 0 | AA20: 0 | AB20: 0 | AC20: 0 | AD20: 0 | AE20: 0 | AF20: 7 | AG20: 21 | AH20: 35 | AI20: 49 | AJ20: 63 | AK20: 77 | AL20: 0 | AM20: 0 | AN20: 0 | AO20: Y | AP20: R | AQ20: 0 | AR20: 0 | AS20: 26 | AT20: 0 | AU20: Y | BC20: 0 | BD20: 0 | BE20: 0 | BF20: 0 | BG20: 0 | BH20: 0 | BI20: N | BJ20: N | BK20: N | BL20: N | BM20: N | BN20: N | BU20: 0 | BV20: 0 | BW20: 0 | BX20: 0 | BY20: 0 | BZ20: 0 | CA20: P | CB20: N | CC20: N | CD20: N | CE20: N | CF20: N | CG20: N | CH20: N | CI20: 0 | CJ20: N | CL20: 0 | CM20: N | CN20: 0 | CO20: N | CP20: N | CQ20: B | CR20: N | CT20: N | CU20: 4 | CV20: N | CW20: N | CY20: N | DA20: Y | DC20: 0 | DD20: S | DG20: N | DH20: N | DI20: N | DJ20: N | DK20: N | DP20: 0 | DQ20: 0 | DR20: 90 | DS20: 90 | DT20: 0 | DU20: 0 | DV20: N | DW20: P | DX20: P | DY20: 17 | DZ20: N | EC20: F | ED20: 5 | EE20: U | EF20: 100 | EG20: N | EH20: N | EI20: N | EJ20: N | EK20: N | EL20: 6 | EM20: N | EO20: 99 | EP20: P | EQ20: Y | ER20: N | ES20: 0 | EV20: Y | EW20: 0 | EX20: N | EY20: N | EZ20: N | FA20: N | FB20: Y | FC20: N | FD20: B | FE20: N | FF20: N | FG20: N | FH20: N | FI20: N | FJ20: N | FK20: N | FL20: N | FM20: 0 | FN20: N | FO20: N | FP20: N | FQ20: N | FR20: 0 | FS20: 0 | FT20: N | FV20: 0 | FY20: N | FZ20: N | GA20: 1 | GB20: M | GC20: N | GD20: N | GE20: N | GF20: 0 | GG20: O | GH20: N | GI20: N | GJ20: N | GK20: Y | GL20: N | GM20: 0 | GN20: 0 | GO20: Y | GP20: Y | GQ20: N | GR20: 0 | GS20: 0 | GT20: 0 | GU20: 0 | GV20: 0 | GW20: N | GX20: Y | HB20: N | HC20: 0 | HD20: N | HE20: Y | HF20: O | HG20: 0 | HH20: 0 | HI20: 0 | HJ20: 0 | HK20: 0 | HL20: 18 | HM20: N | HO20: 0 | HP20: 0 | HR20: 0 | HS20: 0 | HT20: 0 | HU20: 0 | HV20: D | HW20: W | HY20: 0 | HZ20: 0 | IA20: 0 | IB20: N | IC20: N | ID20: N | IE20: N
A21: BQ | B21: KI EBJ | C21: KI EBJ 4,3,2,1 | D21: 106 | E21: On B/S,Program,KI-ID | G21: 8 | H21: 310 | I21: IDR | J21: 31 | K21: 0.08 | L21: 0.15 | M21: 0.08 | N21: 0.15 | O21: N | P21: 1 | Q21: M | R21: 6 | S21: 0 | T21: Y | U21: Y | V21: N | W21: 0 | Y21: 1 | Z21: 0 | AA21: 0 | AB21: 0 | AC21: 0 | AD21: 0 | AE21: 0 | AF21: 7 | AG21: 21 | AH21: 1 | AI21: 0 | AJ21: 0 | AK21: 0 | AL21: 0 | AM21: 0 | AN21: 0 | AO21: Y | AP21: R | AQ21: 0 | AR21: 0 | AS21: 1 | AT21: 0 | AU21: Y | BC21: 0 | BD21: 0 | BE21: 0 | BF21: 0 | BG21: 0 | BH21: 0 | BI21: N | BJ21: N | BK21: N | BL21: N | BM21: N | BN21: N | BU21: 0 | BV21: 0 | BW21: 0 | BX21: 0 | BY21: 0 | BZ21: 0 | CA21: P | CB21: N | CC21: N | CD21: N | CE21: N | CF21: N | CG21: N | CH21: N | CI21: 0 | CJ21: N | CL21: 0 | CM21: N | CN21: 0 | CO21: N | CP21: N | CR21: N | CT21: Y | CU21: 4 | CV21: N | CW21: N | CY21: N | DA21: Y | DC21: 0 | DD21: O | DG21: N | DH21: N | DI21: N | DJ21: N | DK21: N | DP21: 0 | DQ21: 0 | DR21: 90 | DS21: 90 | DT21: 0 | DU21: 0 | DV21: N | DW21: P | DX21: P | DY21: 17 | DZ21: N | EC21: D | ED21: 2 | EE21: R | EF21: 100 | EG21: N | EH21: N | EI21: N | EJ21: N | EK21: N | EL21: 2 | EM21: N | EO21: 99 | EP21: P | EQ21: Y | ER21: N | ES21: 0 | EV21: Y | EW21: 6 | EX21: N | EY21: N | EZ21: N | FA21: N | FB21: Y | FC21: N | FD21: B | FE21: N | FF21: N | FG21: N | FH21: N | FI21: N | FJ21: N | FK21: N | FL21: N | FM21: 0 | FN21: N | FO21: N | FP21: N | FQ21: N | FR21: 0 | FS21: 0 | FT21: N | FV21: 0 | FY21: N | FZ21: N | GA21: 1 | GB21: M | GC21: N | GD21: N | GE21: N | GF21: 0 | GG21: O | GH21: N | GI21: Y | GJ21: N | GK21: Y | GL21: P | GM21: 0 | GN21: 0 | GO21: Y | GP21: Y | GQ21: N | GR21: 2 | GS21: 0 | GT21: 0 | GU21: 0 | GV21: 0 | GW21: N | GX21: Y | HB21: N | HC21: 0 | HD21: N | HE21: N | HG21: 0 | HH21: 0 | HI21: 0 | HJ21: 0 | HK21: 0 | HM21: N | HO21: 0 | HP21: 0 | HR21: 0 | HS21: 0 | HT21: 0 | HU21: 0 | HV21: D | HW21: W | HY21: 0 | HZ21: 0 | IA21: 0 | IB21: N | IC21: N | ID21: N | IE21: N
A22: EP | B22: INV KANPUS | C22: KI PRAKARSA KP PROGR | D22: 205 | E22: POnB,Non Prog,KI-IDR | G22: 8 | H22: 240 | I22: IDR | J22: 31 | K22: 0.06 | L22: 0.3 | M22: 0.06 | N22: 0.3 | O22: N | P22: 1 | Q22: M | R22: 6 | S22: 10 | T22: Y | U22: Y | V22: N | W22: 0 | X22: N | Y22: 1 | Z22: 0 | AA22: 0 | AB22: 0 | AC22: 0 | AD22: 0 | AE22: 0 | AF22: 7 | AG22: 21 | AH22: 35 | AI22: 49 | AJ22: 63 | AK22: 77 | AL22: 0 | AM22: 0 | AN22: 0 | AO22: Y | AP22: R | AQ22: 0 | AR22: 0 | AS22: 1 | AT22: 0 | AU22: Y | BA22: O | BC22: 0 | BD22: 0 | BE22: 0 | BF22: 0 | BG22: 0 | BH22: 0 | BI22: N | BJ22: N | BK22: N | BL22: N | BM22: N | BN22: N | BS22: V | BU22: 0 | BV22: 0 | BW22: 0 | BX22: 0 | BY22: 0 | BZ22: 0 | CA22: P | CB22: N | CC22: N | CD22: N | CE22: N | CF22: N | CG22: N | CH22: Y | CI22: 0 | CJ22: N | CL22: 0 | CM22: N | CN22: 0 | CO22: Y | CP22: N | CQ22: B | CR22: N | CT22: Y | CU22: 4 | CV22: Y | CW22: N | CY22: N | DA22: Y | DC22: 0 | DD22: O | DG22: N | DH22: N | DI22: N | DJ22: N | DK22: N | DP22: 0 | DQ22: 0 | DR22: 90 | DS22: 90 | DT22: 0 | DU22: 0 | DV22: N | DW22: P | DX22: P | DY22: 17 | DZ22: N | EC22: D | ED22: 0 | EE22: R | EF22: 100 | EG22: N | EH22: N | EI22: N | EJ22: N | EK22: N | EL22: 5 | EM22: N | EO22: 99 | EP22: P | EQ22: Y | ER22: N | ES22: 0 | EV22: Y | EW22: 6 | EX22: N | EY22: N | EZ22: N | FA22: N | FB22: N | FC22: N | FD22: B | FE22: N | FF22: N | FG22: N | FH22: N | FI22: N | FJ22: N | FK22: N | FL22: N | FM22: 0 | FN22: N | FO22: N | FP22: N | FQ22: N | FR22: 0 | FS22: 0 | FT22: Y | FV22: 0 | FY22: N | FZ22: N | GA22: 1 | GB22: M | GC22: N | GD22: N | GE22: N | GF22: 0 | GG22: O | GH22: N | GI22: Y | GJ22: N | GK22: Y | GL22: P | GM22: 0 | GN22: 0 | GO22: Y | GP22: Y | GQ22: N | GR22: 0 | GS22: 0 | GT22: 0 | GU22: 0 | GV22: 0 | GW22: N | GX22: N | GY22: C | GZ22: C | HB22: N | HC22: 0 | HD22: N | HE22: N | HG22: 0 | HH22: 0 | HI22: 0 | HJ22: 0 | HK22: 0 | HM22: N | HO22: 0 | HP22: 0 | HR22: 0 | HS22: 0 | HT22: 0 | HU22: 0 | HV22: D | HW22: W | HY22: 0 | HZ22: 0 | IA22: 0 | IB22: N | IC22: N | ID22: N | IE22: N
A23: ER | B23: INV KANPUS | C23: KI PRAKARSA KP DKM2 | D23: 208 | E23: POnB,Non Prog,KI-IDR | G23: 8 | H23: 320 | I23: IDR | J23: 31 | K23: 0.01 | L23: 0.3 | M23: 0.01 | N23: 0.3 | O23: N | P23: 1 | Q23: M | R23: 6 | S23: 10 | T23: Y | U23: Y | V23: N | W23: 0 | X23: N | Y23: 1 | Z23: 0 | AA23: 0 | AB23: 0 | AC23: 0 | AD23: 0 | AE23: 0 | AF23: 7 | AG23: 21 | AH23: 35 | AI23: 49 | AJ23: 63 | AK23: 77 | AL23: 0 | AM23: 0 | AN23: 0 | AO23: Y | AP23: R | AQ23: 0 | AR23: 0 | AS23: 1 | AT23: 0 | AU23: Y | BA23: O | BC23: 0 | BD23: 0 | BE23: 0 | BF23: 0 | BG23: 0 | BH23: 0 | BI23: N | BJ23: N | BK23: N | BL23: N | BM23: N | BN23: N | BS23: V | BU23: 0 | BV23: 0 | BW23: 0 | BX23: 0 | BY23: 0 | BZ23: 0 | CA23: P | CB23: N | CC23: N | CD23: N | CE23: N | CF23: N | CG23: N | CH23: Y | CI23: 0 | CJ23: N | CL23: 0 | CM23: N | CN23: 0 | CO23: Y | CP23: N | CQ23: B | CR23: N | CT23: Y | CU23: 4 | CV23: Y | CW23: N | CY23: N | DA23: Y | DC23: 0 | DD23: O | DG23: N | DH23: N | DI23: N | DJ23: N | DK23: N | DP23: 0 | DQ23: 0 | DR23: 90 | DS23: 90 | DT23: 0 | DU23: 0 | DV23: N | DW23: P | DX23: N | DZ23: N | EC23: D | ED23: 0 | EE23: R | EF23: 100 | EG23: N | EH23: N | EI23: N | EJ23: N | EK23: N | EL23: 5 | EM23: N | EO23: 99 | EP23: P | EQ23: Y | ER23: N | ES23: 0 | EV23: Y | EW23: 6 | EX23: N | EY23: N | EZ23: N | FA23: N | FB23: N | FC23: N | FD23: B | FE23: N | FF23: N | FG23: N | FH23: N | FI23: N | FJ23: N | FK23: N | FL23: N | FM23: 0 | FN23: N | FO23: N | FP23: N | FQ23: N | FR23: 0 | FS23: 0 | FT23: Y | FV23: 0 | FY23: N | FZ23: N | GA23: 1 | GB23: M | GC23: N | GD23: N | GE23: N | GF23: 0 | GH23: N | GI23: Y | GJ23: N | GK23: Y | GL23: P | GM23: 0 | GN23: 0 | GO23: Y | GP23: Y | GQ23: N | GR23: 0 | GS23: 0 | GT23: 0 | GU23: 0 | GV23: 0 | GW23: N | GX23: N | GY23: C | GZ23: C | HB23: N | HC23: 0 | HD23: N | HE23: Y | HF23: O | HG23: 0 | HH23: 0 | HI23: 0.02 | HJ23: 0 | HK23: 0 | HL23: 18 | HM23: N | HO23: 0 | HP23: 0 | HR23: 0 | HS23: 0 | HT23: 0 | HU23: 0 | HV23: D | HW23: W | HY23: 0 | HZ23: 0 | IA23: 0 | IB23: N | IC23: N | ID23: N | IE23: N
A24: EQ | B24: INV KANPUS | C24: KI PRAKARSA KP DKM1 | D24: 207 | E24: POnB,Non Prog,KI-IDR | G24: 8 | H24: 310 | I24: IDR | J24: 31 | K24: 0.001 | L24: 0.3 | M24: 0.001 | N24: 0.3 | O24: N | P24: 3 | Q24: M | R24: 6 | S24: 10 | T24: Y | U24: Y | V24: N | W24: 0 | X24: N | Y24: 1 | Z24: 0 | AA24: 0 | AB24: 0 | AC24: 0 | AD24: 0 | AE24: 0 | AF24: 7 | AG24: 21 | AH24: 35 | AI24: 49 | AJ24: 63 | AK24: 77 | AL24: 0 | AM24: 0 | AN24: 0 | AO24: Y | AP24: R | AQ24: 0 | AR24: 0 | AS24: 1 | AT24: 0 | AU24: Y | BA24: O | BC24: 0 | BD24: 0 | BE24: 0 | BF24: 0 | BG24: 0 | BH24: 0 | BI24: N | BJ24: N | BK24: N | BL24: N | BM24: N | BN24: N | BS24: V | BU24: 0 | BV24: 0 | BW24: 0 | BX24: 0 | BY24: 0 | BZ24: 0 | CA24: P | CB24: N | CC24: N | CD24: N | CE24: N | CF24: N | CG24: N | CH24: Y | CI24: 0 | CJ24: N | CL24: 0 | CM24: N | CN24: 0 | CO24: Y | CP24: N | CQ24: B | CR24: N | CT24: Y | CU24: 4 | CV24: Y | CW24: N | CY24: N | DA24: Y | DC24: 0 | DD24: O | DG24: N | DH24: N | DI24: N | DJ24: N | DK24: N | DP24: 0 | DQ24: 0 | DR24: 90 | DS24: 90 | DT24: 0 | DU24: 0 | DV24: N | DW24: P | DX24: P | DY24: 17 | DZ24: N | EC24: D | ED24: 0 | EE24: R | EF24: 100 | EG24: N | EH24: N | EI24: N | EJ24: N | EK24: N | EL24: 5 | EM24: N | EO24: 99 | EP24: P | EQ24: Y | ER24: N | ES24: 0 | EV24: Y | EW24: 6 | EX24: N | EY24: N | EZ24: N | FA24: N | FB24: N | FC24: N | FD24: B | FE24: N | FF24: N | FG24: N | FH24: N | FI24: N | FJ24: N | FK24: N | FL24: N | FM24: 0 | FN24: N | FO24: N | FP24: N | FQ24: N | FR24: 0 | FS24: 0 | FT24: Y | FV24: 0 | FY24: N | FZ24: N | GA24: 1 | GB24: M | GC24: N | GD24: N | GE24: N | GF24: 0 | GG24: O | GH24: N | GI24: Y | GJ24: N | GK24: Y | GL24: P | GM24: 0 | GN24: 0 | GO24: Y | GP24: Y | GQ24: N | GR24: 0 | GS24: 0 | GT24: 0 | GU24: 0 | GV24: 0 | GW24: N | GX24: N | GY24: C | GZ24: C | HB24: N | HC24: 0 | HD24: N | HE24: Y | HF24: O | HG24: 0 | HH24: 0 | HI24: 0.02 | HJ24: 0 | HK24: 0 | HL24: 18 | HM24: N | HO24: 0 | HP24: 0 | HR24: 0 | HS24: 0 | HT24: 0 | HU24: 0 | HV24: D | HW24: W | HY24: 0 | HZ24: 0 | IA24: 0 | IB24: N | IC24: N | ID24: N | IE24: N
A25: EM | B25: KI SMIEP | C25: KI DLM RANGKA SMIEP | D25: 207 | E25: POnB,Non Prog,KI-IDR | G25: 8 | H25: 310 | I25: IDR | J25: 31 | K25: 0.06 | L25: 0.3 | M25: 0.06 | N25: 0.3 | O25: N | P25: 1 | Q25: M | R25: 6 | S25: 10 | T25: Y | U25: Y | V25: N | W25: 0 | X25: I | Y25: 1 | Z25: 0 | AA25: 0 | AB25: 0 | AC25: 0 | AD25: 0 | AE25: 0 | AF25: 7 | AG25: 21 | AH25: 35 | AI25: 49 | AJ25: 63 | AK25: 77 | AL25: 0 | AM25: 0 | AN25: 0 | AO25: Y | AP25: R | AQ25: 0 | AR25: 0 | AS25: 1 | AT25: 0 | AU25: Y | BC25: 0 | BD25: 0 | BE25: 0 | BF25: 0 | BG25: 0 | BH25: 0 | BI25: N | BJ25: N | BK25: N | BL25: N | BM25: N | BN25: N | BU25: 0 | BV25: 0 | BW25: 0 | BX25: 0 | BY25: 0 | BZ25: 0 | CA25: P | CB25: N | CC25: N | CD25: N | CE25: N | CF25: N | CG25: N | CH25: Y | CI25: 0 | CJ25: N | CL25: 0 | CM25: N | CN25: 0 | CO25: Y | CP25: N | CR25: N | CT25: Y | CU25: 4 | CV25: Y | CW25: N | CY25: N | DA25: Y | DC25: 0 | DD25: O | DG25: N | DH25: N | DI25: N | DJ25: N | DK25: N | DP25: 0 | DQ25: 0 | DR25: 90 | DS25: 90 | DT25: 0 | DU25: 0 | DV25: N | DW25: P | DX25: P | DY25: 17 | DZ25: N | EC25: D | ED25: 0 | EE25: R | EF25: 100 | EG25: N | EH25: N | EI25: N | EJ25: N | EK25: N | EL25: 5 | EM25: N | EO25: 99 | EP25: P | EQ25: Y | ER25: N | ES25: 0 | EV25: Y | EW25: 6 | EX25: N | EY25: N | EZ25: N | FA25: N | FB25: N | FC25: N | FD25: B | FE25: N | FF25: N | FG25: N | FH25: N | FI25: N | FJ25: N | FK25: N | FL25: N | FM25: 0 | FN25: N | FO25: N | FP25: N | FQ25: N | FR25: 0 | FS25: 0 | FT25: Y | FV25: 0 | FY25: N | FZ25: N | GA25: 1 | GB25: M | GC25: N | GD25: N | GE25: N | GF25: 0 | GG25: O | GH25: N | GI25: Y | GJ25: N | GK25: Y | GL25: P | GM25: 0 | GN25: 0 | GO25: Y | GP25: Y | GQ25: N | GR25: 0 | GS25: 0 | GT25: 0 | GU25: 0 | GV25: 0 | GW25: N | GX25: N | GY25: C | GZ25: C | HB25: N | HC25: 0 | HD25: N | HE25: N | HG25: 0 | HH25: 0 | HI25: 0 | HJ25: 0 | HK25: 0 | HM25: N | HO25: 0 | HP25: 0 | HR25: 0 | HS25: 0 | HT25: 0 | HU25: 0 | HV25: D | HW25: W | HY25: 0 | HZ25: 0 | IA25: 0 | IB25: N | IC25: N | ID25: N | IE25: N
A26: EL | B26: KI 75 JUTA | C26: KI S/D 75 JUTA | D26: 206 | E26: POnB,Non Prog,KI-IDR | G26: 8 | H26: 230 | I26: IDR | J26: 31 | K26: 0.06 | L26: 0.3 | M26: 0.06 | N26: 0.3 | O26: N | P26: 1 | Q26: M | R26: 6 | S26: 10 | T26: Y | U26: Y | V26: N | W26: 0 | X26: I | Y26: 1 | Z26: 0 | AA26: 0 | AB26: 0 | AC26: 0 | AD26: 0 | AE26: 0 | AF26: 7 | AG26: 21 | AH26: 35 | AI26: 49 | AJ26: 63 | AK26: 77 | AL26: 0 | AM26: 0 | AN26: 0 | AO26: Y | AP26: R | AQ26: 0 | AR26: 0 | AS26: 1 | AT26: 0 | AU26: Y | BC26: 0 | BD26: 0 | BE26: 0 | BF26: 0 | BG26: 0 | BH26: 0 | BI26: N | BJ26: N | BK26: N | BL26: N | BM26: N | BN26: N | BU26: 0 | BV26: 0 | BW26: 0 | BX26: 0 | BY26: 0 | BZ26: 0 | CA26: P | CB26: N | CC26: N | CD26: N | CE26: N | CF26: N | CG26: N | CH26: Y | CI26: 0 | CJ26: N | CL26: 0 | CM26: N | CN26: 0 | CO26: Y | CP26: N | CQ26: A | CR26: N | CT26: Y | CU26: 4 | CV26: Y | CW26: N | CY26: N | DA26: Y | DC26: 0 | DD26: O | DG26: N | DH26: N | DI26: N | DJ26: N | DK26: N | DP26: 0 | DQ26: 0 | DR26: 90 | DS26: 90 | DT26: 0 | DU26: 0 | DV26: N | DW26: P | DX26: P | DY26: 17 | DZ26: N | EC26: D | ED26: 0 | EE26: R | EF26: 100 | EG26: N | EH26: N | EI26: N | EJ26: N | EK26: N | EL26: 5 | EM26: N | EO26: 99 | EP26: P | EQ26: Y | ER26: N | ES26: 0 | EV26: Y | EW26: 6 | EX26: N | EY26: N | EZ26: N | FA26: N | FB26: N | FC26: N | FD26: B | FE26: N | FF26: N | FG26: N | FH26: N | FI26: N | FJ26: N | FK26: N | FL26: N | FM26: 0 | FN26: N | FO26: N | FP26: N | FQ26: N | FR26: 0 | FS26: 0 | FT26: Y | FV26: 0 | FY26: N | FZ26: N | GA26: 1 | GB26: M | GC26: N | GD26: N | GE26: N | GF26: 0 | GG26: O | GH26: N | GI26: Y | GJ26: N | GK26: Y | GL26: P | GM26: 0 | GN26: 0 | GO26: Y | GP26: Y | GQ26: N | GR26: 0 | GS26: 0 | GT26: 0 | GU26: 0 | GV26: 0 | GW26: N | GX26: N | GY26: C | GZ26: C | HB26: N | HC26: 0 | HD26: N | HE26: N | HG26: 0 | HH26: 0 | HI26: 0 | HJ26: 0 | HK26: 0 | HM26: N | HO26: 0 | HP26: 0 | HR26: 0 | HS26: 0 | HT26: 0 | HU26: 0 | HV26: D | HW26: W | HY26: 0 | HZ26: 0 | IA26: 0 | IB26: N | IC26: N | ID26: N | IE26: N
A27: FE | B27: KRETUNG | C27: PERS-NO-AN JK.PENDEK | D27: 210 | E27: POnB,Non Prog,Konsum | G27: 8 | H27: 230 | I27: IDR | J27: 0 | K27: 0.055 | L27: 0.0551 | M27: 0.055 | N27: 0.0551 | O27: N | P27: 1 | Q27: M | R27: 0 | S27: 0 | T27: Y | U27: Y | V27: N | W27: 0 | X27: I | Y27: 1 | Z27: 0 | AA27: 0 | AB27: 0 | AC27: 0 | AD27: 0 | AE27: 0 | AF27: 7 | AG27: 21 | AH27: 35 | AI27: 49 | AJ27: 63 | AK27: 77 | AL27: 0 | AM27: 0 | AN27: 0 | AO27: Y | AP27: R | AQ27: 0 | AR27: 0 | AS27: 26 | AT27: 0 | AU27: Y | BC27: 0 | BD27: 0 | BE27: 0 | BF27: 0 | BG27: 0 | BH27: 0 | BI27: N | BJ27: N | BK27: N | BL27: N | BM27: N | BN27: N | BO27: V | BU27: 0 | BV27: 0 | BW27: 0 | BX27: 0 | BY27: 0 | BZ27: 0 | CA27: P | CB27: N | CC27: N | CD27: N | CE27: N | CF27: N | CG27: N | CH27: N | CI27: 0 | CJ27: N | CL27: 0 | CM27: N | CN27: 0 | CO27: N | CP27: N | CQ27: B | CR27: N | CT27: Y | CU27: 4 | CV27: N | CW27: N | CY27: N | DA27: N | DC27: 0 | DD27: T | DG27: N | DH27: N | DI27: N | DJ27: N | DK27: N | DP27: 0 | DQ27: 0 | DR27: 90 | DS27: 90 | DT27: 0 | DU27: 0 | DV27: N | DW27: P | DX27: P | DY27: 17 | DZ27: N | EC27: M | ED27: 5 | EE27: U | EF27: 500 | EG27: N | EH27: N | EI27: N | EJ27: Z | EK27: N | EL27: 6 | EM27: N | EO27: 0 | EP27: P | EQ27: N | ER27: N | ES27: 0 | EV27: Y | EW27: 0 | EX27: N | EY27: N | EZ27: N | FA27: N | FB27: Y | FC27: N | FD27: B | FE27: N | FF27: N | FG27: N | FH27: N | FI27: N | FJ27: N | FK27: N | FL27: N | FM27: 0 | FN27: N | FO27: N | FP27: N | FQ27: N | FR27: 0 | FS27: 0 | FT27: N | FV27: 0 | FY27: N | FZ27: N | GA27: 1 | GB27: M | GC27: N | GD27: N | GE27: N | GF27: 0 | GG27: O | GH27: N | GI27: N | GJ27: N | GK27: Y | GL27: N | GM27: 0 | GN27: 0 | GO27: Y | GP27: Y | GQ27: N | GR27: 0 | GS27: 0 | GT27: 0 | GU27: 0 | GV27: 0 | GW27: N | GX27: Y | HB27: N | HC27: 0 | HD27: N | HE27: N | HG27: 0 | HH27: 0 | HI27: 0 | HJ27: 0 | HK27: 0 | HM27: N | HO27: 0 | HP27: 0 | HR27: 0 | HS27: 0 | HT27: 0 | HU27: 0 | HV27: D | HW27: W | HY27: 0 | HZ27: 0 | IA27: 0 | IB27: N | IC27: N | ID27: N | IE27: N
A28: EK | B28: RC INVES | C28: RC INVESTASI | D28: 206 | E28: POnB,Non Prog,KI-IDR | G28: 8 | H28: 230 | I28: IDR | J28: 31 | K28: 0.04 | L28: 0.3 | M28: 0.04 | N28: 0.3 | O28: N | P28: 1 | Q28: M | R28: 6 | S28: 10 | T28: Y | U28: Y | V28: N | W28: 0 | X28: N | Y28: 1 | Z28: 0 | AA28: 0 | AB28: 0 | AC28: 0 | AD28: 0 | AE28: 0 | AF28: 7 | AG28: 21 | AH28: 35 | AI28: 49 | AJ28: 63 | AK28: 77 | AL28: 0 | AM28: 0 | AN28: 0 | AO28: Y | AP28: R | AQ28: 0 | AR28: 0 | AS28: 1 | AT28: 0 | AU28: Y | BC28: 0 | BD28: 0 | BE28: 0 | BF28: 0 | BG28: 0 | BH28: 0 | BI28: N | BJ28: N | BK28: N | BL28: N | BM28: N | BN28: N | BU28: 0 | BV28: 0 | BW28: 0 | BX28: 0 | BY28: 0 | BZ28: 0 | CA28: P | CB28: N | CC28: N | CD28: N | CE28: N | CF28: N | CG28: N | CH28: Y | CI28: 0 | CJ28: N | CL28: 0 | CM28: N | CN28: 0 | CO28: Y | CP28: N | CQ28: B | CR28: N | CT28: Y | CU28: 4 | CV28: Y | CW28: N | CY28: N | DA28: Y | DC28: 0 | DD28: O | DG28: N | DH28: N | DI28: N | DJ28: N | DK28: N | DP28: 0 | DQ28: 0 | DR28: 90 | DS28: 90 | DT28: 0 | DU28: 0 | DV28: N | DW28: P | DX28: P | DY28: 17 | DZ28: N | EC28: D | ED28: 0 | EE28: R | EF28: 100 | EG28: N | EH28: N | EI28: N | EJ28: N | EK28: N | EL28: 5 | EM28: N | EO28: 99 | EP28: P | EQ28: Y | ER28: N | ES28: 0 | EV28: Y | EW28: 6 | EX28: N | EY28: N | EZ28: N | FA28: N | FB28: N | FC28: N | FD28: B | FE28: N | FF28: N | FG28: N | FH28: N | FI28: N | FJ28: N | FK28: N | FL28: N | FM28: 0 | FN28: N | FO28: N | FP28: N | FQ28: N | FR28: 0 | FS28: 0 | FT28: Y | FV28: 0 | FY28: N | FZ28: N | GA28: 1 | GB28: M | GC28: N | GD28: N | GE28: N | GF28: 0 | GG28: O | GH28: N | GI28: Y | GJ28: N | GK28: Y | GL28: P | GM28: 0 | GN28: 0 | GO28: Y | GP28: Y | GQ28: N | GR28: 0 | GS28: 0 | GT28: 0 | GU28: 0 | GV28: 0 | GW28: N | GX28: N | GY28: C | GZ28: C | HB28: N | HC28: 0 | HD28: N | HE28: N | HG28: 0 | HH28: 0 | HI28: 0 | HJ28: 0 | HK28: 0 | HM28: N | HO28: 0 | HP28: 0 | HR28: 0 | HS28: 0 | HT28: 0 | HU28: 0 | HV28: D | HW28: W | HY28: 0 | HZ28: 0 | IA28: 0 | IB28: N | IC28: N | ID28: N | IE28: N
A29: EJ | B29: KIK UMUM | C29: KIK UMUM | D29: 206 | E29: POnB,Non Prog,KI-IDR | G29: 8 | H29: 230 | I29: IDR | J29: 31 | K29: 0.06 | L29: 0.3 | M29: 0.06 | N29: 0.3 | O29: N | P29: 1 | Q29: M | R29: 6 | S29: 10 | T29: Y | U29: Y | V29: N | W29: 0 | X29: N | Y29: 1 | Z29: 0 | AA29: 0 | AB29: 0 | AC29: 0 | AD29: 0 | AE29: 0 | AF29: 7 | AG29: 21 | AH29: 35 | AI29: 49 | AJ29: 63 | AK29: 77 | AL29: 0 | AM29: 0 | AN29: 0 | AO29: Y | AP29: R | AQ29: 0 | AR29: 0 | AS29: 1 | AT29: 0 | AU29: Y | BC29: 0 | BD29: 0 | BE29: 0 | BF29: 0 | BG29: 0 | BH29: 0 | BI29: N | BJ29: N | BK29: N | BL29: N | BM29: N | BN29: N | BU29: 0 | BV29: 0 | BW29: 0 | BX29: 0 | BY29: 0 | BZ29: 0 | CA29: P | CB29: N | CC29: N | CD29: N | CE29: N | CF29: N | CG29: N | CH29: Y | CI29: 0 | CJ29: N | CL29: 0 | CM29: N | CN29: 0 | CO29: Y | CP29: N | CQ29: B | CR29: N | CT29: Y | CU29: 4 | CV29: Y | CW29: N | CY29: N | DA29: Y | DC29: 0 | DD29: O | DG29: N | DH29: N | DI29: N | DJ29: N | DK29: N | DP29: 0 | DQ29: 0 | DR29: 90 | DS29: 90 | DT29: 0 | DU29: 0 | DV29: N | DW29: P | DX29: P | DY29: 17 | DZ29: N | EC29: D | ED29: 0 | EE29: R | EF29: 100 | EG29: N | EH29: N | EI29: N | EJ29: N | EK29: N | EL29: 5 | EM29: N | EO29: 99 | EP29: P | EQ29: Y | ER29: N | ES29: 0 | EV29: Y | EW29: 6 | EX29: N | EY29: N | EZ29: N | FA29: N | FB29: N | FC29: N | FD29: B | FE29: N | FF29: N | FG29: N | FH29: N | FI29: N | FJ29: N | FK29: N | FL29: N | FM29: 0 | FN29: N | FO29: N | FP29: N | FQ29: N | FR29: 0 | FS29: 0 | FT29: Y | FV29: 0 | FY29: N | FZ29: N | GA29: 1 | GB29: M | GC29: N | GD29: N | GE29: N | GF29: 0 | GG29: O | GH29: N | GI29: Y | GJ29: N | GK29: Y | GL29: P | GM29: 0 | GN29: 0 | GO29: Y | GP29: Y | GQ29: N | GR29: 0 | GS29: 0 | GT29: 0 | GU29: 0 | GV29: 0 | GW29: N | GX29: N | GY29: C | GZ29: C | HB29: N | HC29: 0 | HD29: N | HE29: N | HG29: 0 | HH29: 0 | HI29: 0 | HJ29: 0 | HK29: 0 | HM29: N | HO29: 0 | HP29: 0 | HR29: 0 | HS29: 0 | HT29: 0 | HU29: 0 | HV29: D | HW29: W | HY29: 0 | HZ29: 0 | IA29: 0 | IB29: N | IC29: N | ID29: N | IE29: N
A30: EI | B30: KKI | C30: KRD KECIL INV DKM1 | D30: 207 | E30: POnB,Non Prog,KI-IDR | G30: 8 | H30: 310 | I30: IDR | J30: 31 | K30: 0.06 | L30: 0.3 | M30: 0.06 | N30: 0.3 | O30: N | P30: 1 | Q30: M | R30: 6 | S30: 10 | T30: Y | U30: Y | V30: N | W30: 0 | X30: N | Y30: 1 | Z30: 0 | AA30: 0 | AB30: 0 | AC30: 0 | AD30: 0 | AE30: 0 | AF30: 7 | AG30: 21 | AH30: 35 | AI30: 49 | AJ30: 63 | AK30: 77 | AL30: 0 | AM30: 0 | AN30: 0 | AO30: Y | AP30: R | AQ30: 0 | AR30: 0 | AS30: 1 | AT30: 0 | AU30: Y | BC30: 0 | BD30: 0 | BE30: 0 | BF30: 0 | BG30: 0 | BH30: 0 | BI30: N | BJ30: N | BK30: N | BL30: N | BM30: N | BN30: N | BU30: 0 | BV30: 0 | BW30: 0 | BX30: 0 | BY30: 0 | BZ30: 0 | CA30: P | CB30: N | CC30: N | CD30: N | CE30: N | CF30: N | CG30: N | CH30: Y | CI30: 0 | CJ30: N | CL30: 0 | CM30: N | CN30: 0 | CO30: Y | CP30: N | CQ30: B | CR30: N | CT30: Y | CU30: 4 | CV30: Y | CW30: N | CY30: N | DA30: Y | DC30: 0 | DD30: O | DG30: N | DH30: N | DI30: N | DJ30: N | DK30: N | DP30: 0 | DQ30: 0 | DR30: 90 | DS30: 90 | DT30: 0 | DU30: 0 | DV30: N | DW30: P | DX30: P | DY30: 17 | DZ30: N | EC30: D | ED30: 0 | EE30: R | EF30: 100 | EG30: N | EH30: N | EI30: N | EJ30: N | EK30: N | EL30: 5 | EM30: N | EO30: 99 | EP30: P | EQ30: Y | ER30: N | ES30: 0 | EV30: Y | EW30: 6 | EX30: N | EY30: N | EZ30: N | FA30: N | FB30: N | FC30: N | FD30: B | FE30: N | FF30: N | FG30: N | FH30: N | FI30: N | FJ30: N | FK30: N | FL30: N | FM30: 0 | FN30: N | FO30: N | FP30: N | FQ30: N | FR30: 0 | FS30: 0 | FT30: Y | FV30: 0 | FY30: N | FZ30: N | GA30: 1 | GB30: M | GC30: N | GD30: N | GE30: N | GF30: 0 | GG30: O | GH30: N | GI30: Y | GJ30: N | GK30: Y | GL30: P | GM30: 0 | GN30: 0 | GO30: Y | GP30: Y | GQ30: N | GR30: 0 | GS30: 0 | GT30: 0 | GU30: 0 | GV30: 0 | GW30: N | GX30: N | GY30: C | GZ30: C | HB30: N | HC30: 0 | HD30: N | HE30: N | HG30: 0 | HH30: 0 | HI30: 0 | HJ30: 0 | HK30: 0 | HM30: N | HO30: 0 | HP30: 0 | HR30: 0 | HS30: 0 | HT30: 0 | HU30: 0 | HV30: D | HW30: W | HY30: 0 | HZ30: 0 | IA30: 0 | IB30: N | IC30: N | ID30: N | IE30: N
A31: EH | B31: KKI | C31: KRD KECIL INV RITEL | D31: 206 | E31: POnB,Non Prog,KI-IDR | G31: 8 | H31: 230 | I31: IDR | J31: 31 | K31: 0.045 | L31: 0.3 | M31: 0.045 | N31: 0.3 | O31: N | P31: 1 | Q31: M | R31: 6 | S31: 10 | T31: Y | U31: Y | V31: N | W31: 0 | X31: N | Y31: 1 | Z31: 0 | AA31: 0 | AB31: 0 | AC31: 0 | AD31: 0 | AE31: 0 | AF31: 7 | AG31: 21 | AH31: 35 | AI31: 49 | AJ31: 63 | AK31: 77 | AL31: 0 | AM31: 0 | AN31: 0 | AO31: Y | AP31: R | AQ31: 0 | AR31: 0 | AS31: 1 | AT31: 0 | AU31: Y | BC31: 0 | BD31: 0 | BE31: 0 | BF31: 0 | BG31: 0 | BH31: 0 | BI31: N | BJ31: N | BK31: N | BL31: N | BM31: N | BN31: N | BU31: 0 | BV31: 0 | BW31: 0 | BX31: 0 | BY31: 0 | BZ31: 0 | CA31: P | CB31: N | CC31: N | CD31: N | CE31: N | CF31: N | CG31: N | CH31: Y | CI31: 0 | CJ31: N | CL31: 0 | CM31: N | CN31: 0 | CO31: Y | CP31: N | CQ31: B | CR31: N | CT31: Y | CU31: 4 | CV31: Y | CW31: N | CY31: N | DA31: Y | DC31: 0 | DD31: O | DG31: N | DH31: N | DI31: N | DJ31: N | DK31: N | DP31: 0 | DQ31: 0 | DR31: 90 | DS31: 90 | DT31: 0 | DU31: 0 | DV31: N | DW31: P | DX31: P | DY31: 17 | DZ31: N | EC31: D | ED31: 0 | EE31: R | EF31: 100 | EG31: N | EH31: N | EI31: N | EJ31: N | EK31: N | EL31: 5 | EM31: N | EO31: 99 | EP31: P | EQ31: Y | ER31: N | ES31: 0 | EV31: Y | EW31: 6 | EX31: N | EY31: N | EZ31: N | FA31: N | FB31: N | FC31: N | FD31: B | FE31: N | FF31: N | FG31: N | FH31: N | FI31: N | FJ31: N | FK31: N | FL31: N | FM31: 0 | FN31: N | FO31: N | FP31: N | FQ31: N | FR31: 0 | FS31: 0 | FT31: Y | FV31: 0 | FY31: N | FZ31: N | GA31: 1 | GB31: M | GC31: N | GD31: N | GE31: N | GF31: 0 | GG31: O | GH31: N | GI31: Y | GJ31: N | GK31: Y | GL31: P | GM31: 0 | GN31: 0 | GO31: Y | GP31: Y | GQ31: N | GR31: 0 | GS31: 0 | GT31: 0 | GU31: 0 | GV31: 0 | GW31: N | GX31: N | GY31: C | GZ31: C | HB31: N | HC31: 0 | HD31: N | HE31: N | HG31: 0 | HH31: 0 | HI31: 0 | HJ31: 0 | HK31: 0 | HM31: N | HO31: 0 | HP31: 0 | HR31: 0 | HS31: 0 | HT31: 0 | HU31: 0 | HV31: D | HW31: W | HY31: 0 | HZ31: 0 | IA31: 0 | IB31: N | IC31: N | ID31: N | IE31: N
